Workbook

Sheet 102
B1: RMSE | Q1: R2
B2: rvmRadial | C2: rvmPoly | D2: svmRadial | E2: svmPoly | F2: gaussprRadial | G2: gaussprPoly | H2: nnet | I2: knn | J2: treebag | K2: rf | L2: cubist | M2: pls | N2: pcr | O2: ens_greedy | P2: ens_linear | Q2: rvmRadial | R2: rvmPoly | S2: svmRadial | T2: svmPoly | U2: gaussprRadial | V2: gaussprPoly | W2: nnet | X2: knn | Y2: treebag | Z2: rf | AA2: cubist | AB2: pls | AC2: pcr | AD2: ens_greedy | AE2: ens_linear
A3: 1 | B3: 0.67183088 | C3: 0.67802811 | D3: 0.86692734 | E3: 0.82015766 | F3: 1.022861 | G3: 0.87570573 | H3: 0.77424315 | I3: 0.76704237 | J3: 0.91512883 | K3: 0.86464789 | L3: 0.74049651 | M3: 0.85955054 | N3: 0.88404016 | O3: 0.69761533 | P3: 0.6086486 | Q3: 0.83256752 | R3: 0.80197831 | S3: 0.71932539 | T3: 0.75176505 | U3: 0.70748902 | V3: 0.74609153 | W3: 0.7777674 | X3: 0.83286861 | Y3: 0.71269117 | Z3: 0.76854376 | AA3: 0.76744405 | AB3: 0.70582424 | AC3: 0.68290621 | AD3: 0.81188052 | AE3: 0.85023372
A4: 2 | B4: 1.2640447 | C4: 1.198097 | D4: 0.95393463 | E4: 1.1607483 | F4: 1.1975137 | G4: 1.2585423 | H4: 1.2553674 | I4: 1.0377838 | J4: 1.2251361 | K4: 1.1799887 | L4: 1.0282093 | M4: 1.1217809 | N4: 1.1235989 | O4: 1.0662891 | P4: 1.0105345 | Q4: 0.31972696 | R4: 0.38841442 | S4: 0.71351779 | T4: 0.41419646 | U4: 0.53735103 | V4: 0.44118168 | W4: 0.37435333 | X4: 0.68163036 | Y4: 0.3498905 | Z4: 0.41653816 | AA4: 0.60824522 | AB4: 0.45092941 | AC4: 0.45902004 | AD4: 0.51256585 | AE4: 0.55645329
A5: 3 | B5: 1.0151856 | C5: 0.85889019 | D5: 0.97108402 | E5: 0.64947672 | F5: 1.0188892 | G5: 0.79929365 | H5: 0.91828198 | I5: 1.0872868 | J5: 0.9287604 | K5: 0.82582633 | L5: 0.9435983 | M5: 0.84499939 | N5: 0.85405756 | O5: 0.77140649 | P5: 0.76976633 | Q5: 0.51024095 | R5: 0.65857258 | S5: 0.68235235 | T5: 0.76565484 | U5: 0.63786946 | V5: 0.7859891 | W5: 0.63030192 | X5: 0.42729489 | Y5: 0.59597591 | Z5: 0.74790187 | AA5: 0.59448454 | AB5: 0.59367667 | AC5: 0.58314359 | AD5: 0.70137445 | AE5: 0.68784561
A6: 4 | B6: 0.59543381 | C6: 0.597103 | D6: 0.80610019 | E6: 0.73269901 | F6: 0.86352175 | G6: 0.78027654 | H6: 1.2536188 | I6: 0.72626544 | J6: 0.79450073 | K6: 0.88697424 | L6: 0.71411716 | M6: 0.77784248 | N6: 0.74076628 | O6: 0.66603862 | P6: 0.56012098 | Q6: 0.73163373 | R6: 0.75049466 | S6: 0.70972917 | T6: 0.67669982 | U6: 0.68378653 | V6: 0.7377707 | W6: 0.10126182 | X6: 0.59008389 | Y6: 0.64936521 | Z6: 0.51316833 | AA6: 0.70804558 | AB6: 0.6577453 | AC6: 0.67432807 | AD6: 0.71164272 | AE6: 0.80927278
A7: 5 | B7: 0.90838191 | C7: 0.83796286 | D7: 0.77630413 | E7: 0.81127304 | F7: 0.95470595 | G7: 0.8441889 | H7: 1.0461025 | I7: 0.93347782 | J7: 1.0663297 | K7: 1.1543459 | L7: 0.65329259 | M7: 0.76989883 | N7: 0.79907264 | O7: 0.80934091 | P7: 0.95502411 | Q7: 0.52495134 | R7: 0.60452691 | S7: 0.632528 | T7: 0.6412388 | U7: 0.60101221 | V7: 0.55892663 | W7: 0.36856725 | X7: 0.45654768 | Y7: 0.26151317 | Z7: 0.19893905 | AA7: 0.70794046 | AB7: 0.65743264 | AC7: 0.64601808 | AD7: 0.63057998 | AE7: 0.45506582
A8: 6 | B8: 1.2776999 | C8: 1.3078632 | D8: 0.77447929 | E8: 1.2617449 | F8: 0.80057655 | G8: 1.1616237 | H8: 1.4880093 | I8: 1.1513447 | J8: 0.98927185 | K8: 1.239883 | L8: 1.3016544 | M8: 1.1196697 | N8: 1.1105953 | O8: 0.68856116 | P8: 1.0642171 | Q8: 0.29737197 | R8: 0.17749554 | S8: 0.43749392 | T8: 0.073329024 | U8: 0.31391504 | V8: 0.059229903 | W8: 0.089783523 | X8: 0.066404093 | Y8: 0.1125211 | Z8: 0.042243307 | AA8: 0.048388011 | AB8: 0.073962141 | AC8: 0.067480488 | AD8: 0.38088719 | AE8: 0.12048193
A9: 7 | B9: 0.70925408 | C9: 0.59434097 | D9: 0.75011505 | E9: 0.61058186 | F9: 0.76673414 | G9: 0.80046278 | H9: 0.88250988 | I9: 0.91892238 | J9: 0.92363615 | K9: 0.85631028 | L9: 0.67222627 | M9: 0.57321991 | N9: 0.69696933 | O9: 0.69624119 | P9: 0.90531157 | Q9: 0.76266562 | R9: 0.83520426 | S9: 0.69330131 | T9: 0.79026855 | U9: 0.83861416 | V9: 0.66419734 | W9: 0.587448 | X9: 0.5578546 | Y9: 0.50579768 | Z9: 0.61972525 | AA9: 0.77640152 | AB9: 0.80962627 | AC9: 0.71882875 | AD9: 0.7707641 | AE9: 0.55481081
A10: 8 | B10: 0.80636229 | C10: 0.74326007 | D10: 0.52276947 | E10: 0.61968934 | F10: 0.72618012 | G10: 0.54517832 | H10: 0.69979969 | I10: 0.6128222 | J10: 0.78130393 | K10: 0.73361065 | L10: 0.79819422 | M10: 0.71427099 | N10: 0.71681628 | O10: 0.55939337 | P10: 0.45872237 | Q10: 0.38490554 | R10: 0.37192967 | S10: 0.65837379 | T10: 0.51834094 | U10: 0.42780567 | V10: 0.62804532 | W10: 0.53766913 | X10: 0.55730766 | Y10: 0.33169105 | Z10: 0.3792966 | AA10: 0.37390298 | AB10: 0.41858768 | AC10: 0.45798868 | AD10: 0.60444203 | AE10: 0.74147827
A11: 9 | B11: 1.0181375 | C11: 0.88366639 | D11: 0.3912393 | E11: 0.74537142 | F11: 0.40392584 | G11: 0.6480564 | H11: 0.74901531 | I11: 0.60907799 | J11: 0.54063135 | K11: 0.49821367 | L11: 0.50892729 | M11: 0.5861565 | N11: 0.52259809 | O11: 0.56425378 | P11: 0.5466617 | Q11: 0.5416336 | R11: 0.75833298 | S11: 0.75580898 | T11: 0.71372679 | U11: 0.71976074 | V11: 0.71201456 | W11: 0.59590972 | X11: 0.57927799 | Y11: 0.48739236 | Z11: 0.67055989 | AA11: 0.76993205 | AB11: 0.7326855 | AC11: 0.73368989 | AD11: 0.82343246 | AE11: 0.78992928
A12: 10 | B12: 0.82025141 | C12: 0.6101141 | D12: 0.70683515 | E12: 0.60874679 | F12: 0.75296184 | G12: 0.62809488 | H12: 0.90697537 | I12: 0.8604871 | J12: 0.7290166 | K12: 0.80332952 | L12: 0.45248354 | M12: 0.52697984 | N12: 0.48469557 | O12: 0.50562011 | P12: 0.50367703 | Q12: 0.71553968 | R12: 0.79154246 | S12: 0.74722519 | T12: 0.80366299 | U12: 0.8143869 | V12: 0.82744858 | W12: 0.77409495 | X12: 0.5797362 | Y12: 0.75141218 | Z12: 0.68097599 | AA12: 0.87707127 | AB12: 0.83839879 | AC12: 0.85913958 | AD12: 0.8572497 | AE12: 0.87541409
A14: AVG | B14: =AVERAGE(B3:B12) -> 0.90865822 | C14: =AVERAGE(C3:C12) -> 0.83093259 | D14: =AVERAGE(D3:D12) -> 0.75197886 | E14: =AVERAGE(E3:E12) -> 0.80204891 | F14: =AVERAGE(F3:F12) -> 0.85078701 | G14: =AVERAGE(G3:G12) -> 0.83414232 | H14: =AVERAGE(H3:H12) -> 0.99739233 | I14: =AVERAGE(I3:I12) -> 0.87045106 | ... AE14: =AVERAGE(AE3:AE12) -> 0.64409856
A15: MED | B15: =MEDIAN(B3:B12) -> 0.86431666 | C15: =MEDIAN(C3:C12) -> 0.79061147 | D15: =MEDIAN(D3:D12) -> 0.77539171 | E15: =MEDIAN(E3:E12) -> 0.73903521 | F15: =MEDIAN(F3:F12) -> 0.83204915 | G15: =MEDIAN(G3:G12) -> 0.79987821 | H15: =MEDIAN(H3:H12) -> 0.91262867 | I15: =MEDIAN(I3:I12) -> 0.88970474 | ... AE15: =MEDIAN(AE3:AE12) -> 0.71466194

Sheet 459
B1: RMSE | Q1: R2
B2: rvmRadial | C2: rvmPoly | D2: svmRadial | E2: svmPoly | F2: gaussprRadial | G2: gaussprPoly | H2: nnet | I2: knn | J2: treebag | K2: rf | L2: cubist | M2: pls | N2: pcr | O2: ens_greedy | P2: ens_linear | Q2: rvmRadial | R2: rvmPoly | S2: svmRadial | T2: svmPoly | U2: gaussprRadial | V2: gaussprPoly | W2: nnet | X2: knn | Y2: treebag | Z2: rf | AA2: cubist | AB2: pls | AC2: pcr | AD2: ens_greedy | AE2: ens_linear
A3: 1 | B3: 1.0110117 | C3: 1.1050954 | D3: 1.2437336 | E3: 1.2678096 | F3: 1.1920326 | G3: 1.2107111 | H3: 1.2476421 | I3: 1.2590637 | J3: 1.5273003 | K3: 1.3808646 | L3: 1.1694682 | M3: 1.2243441 | N3: 1.1169309 | O3: 1.1517619 | P3: 1.1576929 | Q3: 0.47494996 | R3: 0.34253706 | S3: 0.15887375 | T3: 0.22679545 | U3: 0.24881684 | V3: 0.24038643 | W3: 0.22299027 | X3: 0.15226227 | Y3: 0.00022062445 | Z3: 0.03437042 | AA3: 0.28965619 | AB3: 0.24654915 | AC3: 0.32937449 | AD3: 0.28659363 | AE3: 0.29660644
A4: 2 | B4: 0.77172028 | C4: 0.72566267 | D4: 0.87634704 | E4: 0.66675357 | F4: 0.87212405 | G4: 1.1883816 | H4: 0.84162761 | I4: 0.79557545 | J4: 0.8563071 | K4: 0.84193594 | L4: 0.86028683 | M4: 0.65690589 | N4: 0.6970947 | O4: 0.81024109 | P4: 0.82782455 | Q4: 0.58843097 | R4: 0.64166124 | S4: 0.46898659 | T4: 0.73776137 | U4: 0.71415148 | V4: 0.10970018 | W4: 0.55403165 | X4: 0.65349007 | Y4: 0.54892253 | Z4: 0.56791878 | AA4: 0.52011501 | AB4: 0.72147976 | AC4: 0.67698706 | AD4: 0.57173953 | AE4: 0.54741228
A5: 3 | B5: 1.2204064 | C5: 0.98630267 | D5: 1.1390039 | E5: 0.89430091 | F5: 1.2546549 | G5: 0.91536555 | H5: 0.90117543 | I5: 1.1797819 | J5: 1.2580603 | K5: 1.1330497 | L5: 0.96417172 | M5: 0.88413242 | N5: 0.91412922 | O5: 0.89803746 | P5: 0.98047204 | Q5: 0.58565381 | R5: 0.66816018 | S5: 0.63575838 | T5: 0.73540631 | U5: 0.79207121 | V5: 0.76023293 | W5: 0.72191926 | X5: 0.56226133 | Y5: 0.56567953 | Z5: 0.6756898 | AA5: 0.71345138 | AB5: 0.77119738 | AC5: 0.73120573 | AD5: 0.73165797 | AE5: 0.68249957
A6: 4 | B6: 2.344952 | C6: 0.96035173 | D6: 1.7829693 | E6: 1.2407117 | F6: 1.7468594 | G6: 1.3054421 | H6: 1.8316501 | I6: 1.4069594 | J6: 1.5422972 | K6: 1.466261 | L6: 1.3013873 | M6: 1.1606272 | N6: 1.1951255 | O6: 1.069219 | P6: 0.87460157 | Q6: 0.0021086323 | R6: 0.79876036 | S6: 0.22521769 | T6: 0.6342531 | U6: 0.37233193 | V6: 0.65709407 | W6: 0.17838426 | X6: 0.57139366 | Y6: 0.61336984 | Z6: 0.66571384 | AA6: 0.58424107 | AB6: 0.70738868 | AC6: 0.70329601 | AD6: 0.76905425 | AE6: 0.83558787
A7: 5 | B7: 1.1023715 | C7: 0.94564468 | D7: 1.0585712 | E7: 1.2614865 | F7: 0.77119105 | G7: 1.1247197 | H7: 1.8198128 | I7: 1.0581743 | J7: 0.86493297 | K7: 0.96000226 | L7: 0.89012529 | M7: 0.94707495 | N7: 0.9534328 | O7: 1.2001352 | P7: 1.2579831 | Q7: 0.27934513 | R7: 0.53498093 | S7: 0.098831822 | T7: 0.2979685 | U7: 0.41441133 | V7: 0.26682946 | W7: 0.00031989324 | X7: 0.096677086 | Y7: 0.26188237 | Z7: 0.13324161 | AA7: 0.4123216 | AB7: 0.49480358 | AC7: 0.41174094 | AD7: 0.17328839 | AE7: 0.15583825
A8: 6 | B8: 1.1448525 | C8: 0.82378768 | D8: 0.7125806 | E8: 0.79307535 | F8: 1.0927902 | G8: 0.78829964 | H8: 0.88020947 | I8: 0.99092051 | J8: 0.98032 | K8: 0.92822699 | L8: 0.69898117 | M8: 0.81048975 | N8: 0.81729471 | O8: 0.76304947 | P8: 0.62368777 | Q8: 0.36050001 | R8: 0.66630478 | S8: 0.8560781 | T8: 0.78315251 | U8: 0.71165487 | V8: 0.69924401 | W8: 0.61543005 | X8: 0.7869324 | Y8: 0.79398653 | Z8: 0.83839382 | AA8: 0.80508633 | AB8: 0.67348129 | AC8: 0.66456846 | AD8: 0.76080694 | AE8: 0.90788572
A9: 7 | B9: 1.3017051 | C9: 0.98496096 | D9: 1.1267403 | E9: 0.91986127 | F9: 1.156445 | G9: 0.92857318 | H9: 1.311318 | I9: 1.0805383 | J9: 1.6086801 | K9: 1.3489817 | L9: 1.272613 | M9: 1.0363026 | N9: 0.95041596 | O9: 0.99667601 | P9: 0.84266253 | Q9: 0.35098446 | R9: 0.61979994 | S9: 0.54674308 | T9: 0.69492317 | U9: 0.66865521 | V9: 0.67822209 | W9: 0.33247305 | X9: 0.68846816 | Y9: 0.037298543 | Z9: 0.25931783 | AA9: 0.49308214 | AB9: 0.55734374 | AC9: 0.64514788 | AD9: 0.7057202 | AE9: 0.85772589
A10: 8 | B10: 0.9751789 | C10: 0.53281367 | D10: 0.7762799 | E10: 0.5014589 | F10: 0.76224812 | G10: 0.70074937 | H10: 1.2890184 | I10: 0.87033229 | J10: 0.80679072 | K10: 0.77345845 | L10: 0.50932537 | M10: 0.52962826 | N10: 0.5496315 | O10: 0.7449767 | P10: 0.91475706 | Q10: 0.33782178 | R10: 0.80746734 | S10: 0.58581525 | T10: 0.83710924 | U10: 0.82090915 | V10: 0.69831175 | W10: 0.46072674 | X10: 0.47732488 | Y10: 0.61405179 | Z10: 0.61628687 | AA10: 0.8264155 | AB10: 0.81169837 | AC10: 0.79132974 | AD10: 0.65003952 | AE10: 0.50314939
A11: 9 | B11: 0.7952844 | C11: 0.85343352 | D11: 0.82401979 | E11: 0.82032953 | F11: 0.84017786 | G11: 0.74924914 | H11: 1.1569916 | I11: 0.84986783 | J11: 0.83203967 | K11: 0.8696883 | L11: 0.78010284 | M11: 0.82157996 | N11: 0.80252718 | O11: 0.73658051 | P11: 0.75776158 | Q11: 0.59428215 | R11: 0.47192426 | S11: 0.59077872 | T11: 0.5342314 | U11: 0.50105357 | V11: 0.61535899 | W11: 0.37150705 | X11: 0.54111252 | Y11: 0.71241805 | Z11: 0.58850653 | AA11: 0.61316782 | AB11: 0.49704578 | AC11: 0.5183425 | AD11: 0.64524733 | AE11: 0.65501006
A12: 10 | B12: 0.87680974 | C12: 0.72579854 | D12: 0.68785324 | E12: 0.81499758 | F12: 0.85031937 | G12: 0.72473915 | H12: 0.80454324 | I12: 0.74016891 | J12: 0.97751741 | K12: 0.91173953 | L12: 0.79129111 | M12: 0.76670299 | N12: 0.78950874 | O12: 0.71438992 | P12: 0.69929126 | Q12: 0.52840593 | R12: 0.68328957 | S12: 0.68867488 | T12: 0.54819815 | U12: 0.6669668 | V12: 0.6514566 | W12: 0.59490999 | X12: 0.70512881 | Y12: 0.35651413 | Z12: 0.47825404 | AA12: 0.59972639 | AB12: 0.64207446 | AC12: 0.60461222 | AD12: 0.67940078 | AE12: 0.7246286
A14: AVG | B14: =AVERAGE(B3:B12) -> 1.1544292 | C14: =AVERAGE(C3:C12) -> 0.86438515 | D14: =AVERAGE(D3:D12) -> 1.0228099 | E14: =AVERAGE(E3:E12) -> 0.91807849 | F14: =AVERAGE(F3:F12) -> 1.0538843 | G14: =AVERAGE(G3:G12) -> 0.96362305 | H14: =AVERAGE(H3:H12) -> 1.2083989 | I14: =AVERAGE(I3:I12) -> 1.0231382 | ... AE14: =AVERAGE(AE3:AE12) -> 0.61663441
A15: MEDIAN | B15: =MEDIAN(B3:B12) -> 1.0566916 | C15: =MEDIAN(C3:C12) -> 0.8995391 | D15: =MEDIAN(D3:D12) -> 0.96745913 | E15: =MEDIAN(E3:E12) -> 0.85731522 | F15: =MEDIAN(F3:F12) -> 0.98245713 | G15: =MEDIAN(G3:G12) -> 0.92196937 | H15: =MEDIAN(H3:H12) -> 1.2023169 | I15: =MEDIAN(I3:I12) -> 1.0245474 | ... AE15: =MEDIAN(AE3:AE12) -> 0.66875482

Sheet 854
B1: RMSE | Q1: R2
B2: rvmRadial | C2: rvmPoly | D2: svmRadial | E2: svmPoly | F2: gaussprRadial | G2: gaussprPoly | H2: nnet | I2: knn | J2: treebag | K2: rf | L2: cubist | M2: pls | N2: pcr | O2: ens_greedy | P2: ens_linear | Q2: rvmRadial | R2: rvmPoly | S2: svmRadial | T2: svmPoly | U2: gaussprRadial | V2: gaussprPoly | W2: nnet | X2: knn | Y2: treebag | Z2: rf | AA2: cubist | AB2: pls | AC2: pcr | AD2: ens_greedy | AE2: ens_linear
A3: 1 | B3: 0.57481939 | C3: 0.91213115 | D3: 0.80821936 | E3: 0.89730892 | F3: 0.81000779 | G3: 0.81516248 | H3: 1.1358113 | I3: 0.75346953 | J3: 0.73054954 | K3: 0.87146435 | L3: 0.80497212 | M3: 0.79254301 | N3: 0.78579229 | O3: 0.73671396 | P3: 0.90600243 | Q3: 0.74466095 | R3: 0.43952655 | S3: 0.59270732 | T3: 0.42933088 | U3: 0.50662308 | V3: 0.63216567 | W3: 0.33543222 | X3: 0.5770836 | Y3: 0.62254058 | Z3: 0.40470503 | AA3: 0.48989913 | AB3: 0.51745631 | AC3: 0.53410261 | AD3: 0.63176146 | AE3: 0.54517918
A4: 2 | B4: 0.9101253 | C4: 0.79617098 | D4: 0.6543988 | E4: 0.9232723 | F4: 0.91412856 | G4: 0.91502459 | H4: 0.99134396 | I4: 0.7874554 | J4: 0.95625359 | K4: 0.92579756 | L4: 0.66173258 | M4: 0.92371324 | N4: 0.84794762 | O4: 0.75408589 | P4: 1.0024763 | Q4: 0.60463995 | R4: 0.66269518 | S4: 0.86570108 | T4: 0.59689275 | U4: 0.69828848 | V4: 0.57533737 | W4: 0.59954611 | X4: 0.75264596 | Y4: 0.61413315 | Z4: 0.66929452 | AA4: 0.76879044 | AB4: 0.57757701 | AC4: 0.63455314 | AD4: 0.70330977 | AE4: 0.57392885
A5: 3 | B5: 1.0192864 | C5: 1.2103357 | D5: 1.1419288 | E5: 1.3693213 | F5: 1.445469 | G5: 1.3790299 | H5: 1.1897473 | I5: 1.2684192 | J5: 1.3307011 | K5: 1.3469481 | L5: 1.22374 | M5: 1.2753606 | N5: 1.212591 | O5: 1.1901488 | P5: 1.1433984 | Q5: 0.79610703 | R5: 0.62787506 | S5: 0.66674536 | T5: 0.45115516 | U5: 0.59850441 | V5: 0.58821421 | W5: 0.59194143 | X5: 0.68962127 | Y5: 0.70772771 | Z5: 0.64990868 | AA5: 0.64000917 | AB5: 0.56086969 | AC5: 0.60581947 | AD5: 0.63657838 | AE5: 0.65288408
A6: 4 | B6: 1.0386991 | C6: 1.0189778 | D6: 1.1148954 | E6: 1.0036755 | F6: 1.0484944 | G6: 1.0407544 | H6: 1.2374965 | I6: 1.033 | J6: 0.95679744 | K6: 0.95443129 | L6: 0.91142892 | M6: 0.99665041 | N6: 0.99038793 | O6: 0.9426227 | P6: 1.0209661 | Q6: 0.35468236 | R6: 0.36271668 | S6: 0.31196026 | T6: 0.40518713 | U6: 0.40814443 | V6: 0.38084956 | W6: 0.22770535 | X6: 0.31719638 | Y6: 0.51410016 | Z6: 0.50728336 | AA6: 0.5002744 | AB6: 0.40893026 | AC6: 0.40178773 | AD6: 0.46362081 | AE6: 0.34466925
A7: 5 | B7: 1.0050585 | C7: 1.1177209 | D7: 0.94443634 | E7: 1.0558735 | F7: 1.2223926 | G7: 1.115044 | H7: 0.78088522 | I7: 1.0477829 | J7: 1.2806903 | K7: 1.1970241 | L7: 1.0352296 | M7: 1.0293626 | N7: 1.0037172 | O7: 0.98005432 | P7: 0.91125155 | Q7: 0.70853916 | R7: 0.47977539 | S7: 0.64311632 | T7: 0.60701872 | U7: 0.63548652 | V7: 0.60876309 | W7: 0.77577545 | X7: 0.5114236 | Y7: 0.37182324 | Z7: 0.43820542 | AA7: 0.57895917 | AB7: 0.59377907 | AC7: 0.65135954 | AD7: 0.67532507 | AE7: 0.68841126
A8: 6 | B8: 1.6264752 | C8: 1.1312881 | D8: 0.9826516 | E8: 1.009674 | F8: 1.2304478 | G8: 1.1060051 | H8: 0.83908683 | I8: 1.2670973 | J8: 1.2887817 | K8: 1.2239839 | L8: 1.0739723 | M8: 1.1607215 | N8: 1.1147147 | O8: 0.97458578 | P8: 1.1034571 | Q8: 0.18225284 | R8: 0.54249076 | S8: 0.71519203 | T8: 0.67662901 | U8: 0.65685862 | V8: 0.69510093 | W8: 0.73731025 | X8: 0.40384342 | Y8: 0.39871346 | Z8: 0.57380469 | AA8: 0.60491776 | AB8: 0.50501217 | AC8: 0.5477152 | AD8: 0.68860166 | AE8: 0.56021085
A9: 7 | B9: 0.98960281 | C9: 0.850562 | D9: 0.95940048 | E9: 0.85743541 | F9: 0.93547025 | G9: 0.92540845 | H9: 0.86074528 | I9: 0.66849466 | J9: 1.1747156 | K9: 1.0562902 | L9: 0.76437522 | M9: 0.82661245 | N9: 0.79982153 | O9: 0.78760122 | P9: 0.80414973 | Q9: 0.50416901 | R9: 0.56617495 | S9: 0.34139961 | T9: 0.53224056 | U9: 0.54726801 | V9: 0.37027957 | W9: 0.47702723 | X9: 0.69178843 | Y9: 0.091883561 | Z9: 0.24349138 | AA9: 0.71096283 | AB9: 0.58448045 | AC9: 0.61528029 | AD9: 0.59627108 | AE9: 0.52588736
A10: 8 | B10: 1.0819018 | C10: 1.0172906 | D10: 0.84724545 | E10: 0.87147007 | F10: 1.0219832 | G10: 0.92383515 | H10: 1.2928234 | I10: 0.95056323 | J10: 1.1196731 | K10: 1.03749 | L10: 0.82464591 | M10: 1.0052456 | N10: 0.93470773 | O10: 0.96391292 | P10: 0.83561345 | Q10: 0.36298717 | R10: 0.42952517 | S10: 0.59291866 | T10: 0.58542046 | U10: 0.52207275 | V10: 0.55342022 | W10: 0.21952557 | X10: 0.48009329 | Y10: 0.27789376 | Z10: 0.3807264 | AA10: 0.6321093 | AB10: 0.46595914 | AC10: 0.53901565 | AD10: 0.48905237 | AE10: 0.63711478
A11: 9 | B11: 1.594231 | C11: 1.1706908 | D11: 0.89656104 | E11: 0.98895421 | F11: 1.0245563 | G11: 0.87988678 | H11: 1.3687663 | I11: 0.96989392 | J11: 0.87550126 | K11: 0.89022472 | L11: 1.1222508 | M11: 0.98764173 | N11: 0.91819148 | O11: 0.90315207 | P11: 1.0446449 | Q11: 0.027063493 | R11: 0.16009461 | S11: 0.43824582 | T11: 0.30284745 | U11: 0.29412881 | V11: 0.62716929 | W11: 0.14482373 | X11: 0.354447 | Y11: 0.57338292 | Z11: 0.5200759 | AA11: 0.1992817 | AB11: 0.3117949 | AC11: 0.40582868 | AD11: 0.43294391 | AE11: 0.2678302
A12: 10 | B12: 0.89141111 | C12: 0.85620952 | D12: 0.93107911 | E12: 1.6534045 | F12: 0.86850802 | G12: 1.0975562 | H12: 1.2497656 | I12: 0.67703988 | J12: 0.88705298 | K12: 1.1448637 | L12: 0.55515305 | M12: 0.54206678 | N12: 0.38285481 | O12: 0.74303552 | P12: 0.7565373 | Q12: 0.64269927 | R12: 0.41832893 | S12: 0.47723388 | T12: 0.23194006 | U12: 0.69230994 | V12: 0.33565936 | W12: 0.19051449 | X12: 0.60493381 | Y12: 0.52176588 | Z12: 0.16689561 | AA12: 0.70835287 | AB12: 0.72441738 | AC12: 0.86467273 | AD12: 0.53757325 | AE12: 0.67461918
A14: AVG | B14: =AVERAGE(B3:B12) -> 1.0731611 | C14: =AVERAGE(C3:C12) -> 1.0081378 | D14: =AVERAGE(D3:D12) -> 0.92808164 | E14: =AVERAGE(E3:E12) -> 1.063039 | F14: =AVERAGE(F3:F12) -> 1.0521458 | G14: =AVERAGE(G3:G12) -> 1.0197707 | H14: =AVERAGE(H3:H12) -> 1.0946472 | I14: =AVERAGE(I3:I12) -> 0.94232161 | ... AE14: =AVERAGE(AE3:AE12) -> 0.5470735
A15: MEDIAN | B15: =MEDIAN(B3:B12) -> 1.0121725 | C15: =MEDIAN(C3:C12) -> 1.0181342 | D15: =MEDIAN(D3:D12) -> 0.93775773 | E15: =MEDIAN(E3:E12) -> 0.99631484 | F15: =MEDIAN(F3:F12) -> 1.0232698 | G15: =MEDIAN(G3:G12) -> 0.98308143 | H15: =MEDIAN(H3:H12) -> 1.1627793 | I15: =MEDIAN(I3:I12) -> 0.96022858 | ... AE15: =MEDIAN(AE3:AE12) -> 0.56706985

Sheet 912
B1: RMSE | Q1: R2
B2: rvmRadial | C2: rvmPoly | D2: svmRadial | E2: svmPoly | F2: gaussprRadial | G2: gaussprPoly | H2: nnet | I2: knn | J2: treebag | K2: rf | L2: cubist | M2: pls | N2: pcr | O2: ens_greedy | P2: ens_linear | Q2: rvmRadial | R2: rvmPoly | S2: svmRadial | T2: svmPoly | U2: gaussprRadial | V2: gaussprPoly | W2: nnet | X2: knn | Y2: treebag | Z2: rf | AA2: cubist | AB2: pls | AC2: pcr | AD2: ens_greedy | AE2: ens_linear
A3: 1 | B3: 0.92342382 | C3: 0.70848736 | D3: 0.70219521 | E3: 0.83636987 | F3: 0.99654666 | G3: 0.72105082 | H3: 0.9279322 | I3: 0.96314987 | J3: 1.0350281 | K3: 1.0333466 | L3: 0.80210597 | M3: 0.85929653 | N3: 0.80423097 | O3: 0.67022915 | P3: 0.65869351 | Q3: 0.62559427 | R3: 0.80232172 | S3: 0.81330341 | T3: 0.70823315 | U3: 0.7361111 | V3: 0.80202298 | W3: 0.65124856 | X3: 0.67530607 | Y3: 0.58677031 | Z3: 0.57379614 | AA3: 0.71774766 | AB3: 0.66908135 | AC3: 0.71407607 | AD3: 0.85373327 | AE3: 0.86604
A4: 2 | B4: 1.2412726 | C4: 0.98740124 | D4: 0.97283037 | E4: 0.99782929 | F4: 1.0351968 | G4: 0.98012486 | H4: 1.227837 | I4: 0.93826222 | J4: 0.99616141 | K4: 1.0108154 | L4: 0.9038747 | M4: 1.0079899 | N4: 1.0148943 | O4: 0.95320952 | P4: 1.0879903 | Q4: 0.19933444 | R4: 0.34441656 | S4: 0.38327202 | T4: 0.33821773 | U4: 0.33758381 | V4: 0.36180162 | W4: 0.13196715 | X4: 0.42789606 | Y4: 0.3810854 | Z4: 0.35346299 | AA4: 0.48387841 | AB4: 0.33323313 | AC4: 0.31489277 | AD4: 0.38863233 | AE4: 0.21158997
A5: 3 | B5: 1.1997805 | C5: 1.1918441 | D5: 1.1879638 | E5: 1.110613 | F5: 1.1578356 | G5: 1.0516609 | H5: 1.4764634 | I5: 1.2777859 | J5: 1.400678 | K5: 1.3632812 | L5: 1.2825899 | M5: 1.104836 | N5: 1.0414053 | O5: 1.2382557 | P5: 1.133101 | Q5: 0.18678855 | R5: 0.20768137 | S5: 0.14587112 | T5: 0.22578608 | U5: 0.21068542 | V5: 0.2935598 | W5: 0.063295191 | X5: 0.081381516 | Y5: 0.06763878 | Z5: 0.060946046 | AA5: 0.13948868 | AB5: 0.32991816 | AC5: 0.40802824 | AD5: 0.166803 | AE5: 0.31409448
A6: 4 | B6: 0.89450821 | C6: 0.91828208 | D6: 0.77885074 | E6: 0.85732283 | F6: 0.8675441 | G6: 0.83934488 | H6: 1.0156996 | I6: 0.82438785 | J6: 0.83291789 | K6: 0.75540719 | L6: 0.87611573 | M6: 0.9545755 | N6: 0.88806853 | O6: 0.81906029 | P6: 0.82483081 | Q6: 0.40992425 | R6: 0.35562174 | S6: 0.50073299 | T6: 0.39759817 | U6: 0.42552501 | V6: 0.42790776 | W6: 0.32612753 | X6: 0.43318309 | Y6: 0.49070049 | Z6: 0.58914175 | AA6: 0.49871396 | AB6: 0.27696234 | AC6: 0.39056315 | AD6: 0.45744275 | AE6: 0.43527571
A7: 5 | B7: 0.74639797 | C7: 0.73504496 | D7: 0.73312485 | E7: 0.87271678 | F7: 0.94408188 | G7: 0.81985435 | H7: 1.2215853 | I7: 0.72450673 | J7: 0.97773623 | K7: 0.95022476 | L7: 0.76713937 | M7: 0.83097978 | N7: 0.80878928 | O7: 0.73317951 | P7: 0.65857127 | Q7: 0.30487322 | R7: 0.49920189 | S7: 0.37932186 | T7: 0.47021182 | U7: 0.4401608 | V7: 0.45058001 | W7: 0.12991872 | X7: 0.29427681 | Y7: 0.21477119 | Z7: 0.20156827 | AA7: 0.48602269 | AB7: 0.45293436 | AC7: 0.41363156 | AD7: 0.48629216 | AE7: 0.48264998
A8: 6 | B8: 1.3782157 | C8: 0.75483861 | D8: 1.0550775 | E8: 0.746303 | F8: 1.2630206 | G8: 0.83804041 | H8: 0.82351052 | I8: 1.4042057 | J8: 1.2327819 | K8: 1.1633525 | L8: 0.73860664 | M8: 0.83203746 | N8: 0.75215407 | O8: 0.68433546 | P8: 0.81565498 | Q8: 0.63207095 | R8: 0.87263205 | S8: 0.82968291 | T8: 0.84982163 | U8: 0.90624128 | V8: 0.83767096 | W8: 0.82598841 | X8: 0.61761402 | Y8: 0.77602099 | Z8: 0.82783276 | AA8: 0.90224702 | AB8: 0.90237865 | AC8: 0.92050245 | AD8: 0.90116142 | AE8: 0.84020412
A9: 7 | B9: 0.93210701 | C9: 0.97340406 | D9: 1.0204756 | E9: 1.0290558 | F9: 1.1102131 | G9: 1.0166403 | H9: 1.0528525 | I9: 0.98018458 | J9: 1.0648805 | K9: 1.0720713 | L9: 1.0212931 | M9: 1.0684228 | N9: 1.0505199 | O9: 0.89229542 | P9: 0.89899098 | Q9: 0.68777702 | R9: 0.58095748 | S9: 0.55092677 | T9: 0.54943693 | U9: 0.59201884 | V9: 0.57769061 | W9: 0.58156509 | X9: 0.74449194 | Y9: 0.54649702 | Z9: 0.57887048 | AA9: 0.58671327 | AB9: 0.54389948 | AC9: 0.53256276 | AD9: 0.6478514 | AE9: 0.65391014
A10: 8 | B10: 1.2844553 | C10: 0.93918275 | D10: 1.0827652 | E10: 0.93239121 | F10: 1.1148622 | G10: 0.96248713 | H10: 1.19054 | I10: 0.87273275 | J10: 1.1534567 | K10: 1.2191448 | L10: 1.1105678 | M10: 1.0122862 | N10: 1.0163942 | O10: 0.89875246 | P10: 0.96362704 | Q10: 0.27397246 | R10: 0.6249186 | S10: 0.4178697 | T10: 0.60285333 | U10: 0.62268569 | V10: 0.67292346 | W10: 0.44756157 | X10: 0.67185507 | Y10: 0.37407359 | Z10: 0.2640577 | AA10: 0.38118395 | AB10: 0.53645479 | AC10: 0.52703828 | AD10: 0.70768972 | AE10: 0.54478842
A11: 9 | B11: 0.85668337 | C11: 0.82568663 | D11: 1.1599176 | E11: 0.79434137 | F11: 1.0202926 | G11: 0.94173821 | H11: 0.57413575 | I11: 1.0229697 | J11: 1.0392171 | K11: 1.0047739 | L11: 1.0169905 | M11: 0.86426162 | N11: 0.84118761 | O11: 0.82615509 | P11: 0.77404643 | Q11: 0.64371883 | R11: 0.62329128 | S11: 0.22607791 | T11: 0.59532314 | U11: 0.38934284 | V11: 0.41916757 | W11: 0.81739959 | X11: 0.32610162 | Y11: 0.28774768 | Z11: 0.37496639 | AA11: 0.39267518 | AB11: 0.54105731 | AC11: 0.63191353 | AD11: 0.59401623 | AE11: 0.62688047
A12: 10 | B12: 2.4875313 | C12: 1.435778 | D12: 1.708413 | E12: 1.299722 | F12: 1.6270588 | G12: 0.99781092 | H12: 1.3450776 | I12: 1.3305952 | J12: 1.3241287 | K12: 1.2450486 | L12: 1.3295398 | M12: 1.2831803 | N12: 1.1937799 | O12: 1.1337174 | P12: 1.0999005 | Q12: 0.0040611707 | R12: 0.43340886 | S12: 0.14051634 | T12: 0.48969848 | U12: 0.19904664 | V12: 0.72518455 | W12: 0.45813286 | X12: 0.46801325 | Y12: 0.5323756 | Z12: 0.56706303 | AA12: 0.46074081 | AB12: 0.52389453 | AC12: 0.57029794 | AD12: 0.60553296 | AE12: 0.66000072
A14: AVG | B14: =AVERAGE(B3:B12) -> 1.1944376 | C14: =AVERAGE(C3:C12) -> 0.94699498 | D14: =AVERAGE(D3:D12) -> 1.0401614 | E14: =AVERAGE(E3:E12) -> 0.94766652 | F14: =AVERAGE(F3:F12) -> 1.1136652 | G14: =AVERAGE(G3:G12) -> 0.91687527 | H14: =AVERAGE(H3:H12) -> 1.0855634 | I14: =AVERAGE(I3:I12) -> 1.0338781 | ... AE14: =AVERAGE(AE3:AE12) -> 0.5635434
A15: MEDIAN | B15: =MEDIAN(B3:B12) -> 1.0659438 | C15: =MEDIAN(C3:C12) -> 0.92873242 | D15: =MEDIAN(D3:D12) -> 1.0377766 | E15: =MEDIAN(E3:E12) -> 0.90255399 | F15: =MEDIAN(F3:F12) -> 1.0727049 | G15: =MEDIAN(G3:G12) -> 0.95211267 | H15: =MEDIAN(H3:H12) -> 1.1216962 | I15: =MEDIAN(I3:I12) -> 0.97166722 | ... AE15: =MEDIAN(AE3:AE12) -> 0.58583445

Sheet 1257
B1: RMSE | Q1: R2
B2: rvmRadial | C2: rvmPoly | D2: svmRadial | E2: svmPoly | F2: gaussprRadial | G2: gaussprPoly | H2: nnet | I2: knn | J2: treebag | K2: rf | L2: cubist | M2: pls | N2: pcr | O2: ens_greedy | P2: ens_linear | Q2: rvmRadial | R2: rvmPoly | S2: svmRadial | T2: svmPoly | U2: gaussprRadial | V2: gaussprPoly | W2: nnet | X2: knn | Y2: treebag | Z2: rf | AA2: cubist | AB2: pls | AC2: pcr | AD2: ens_greedy | AE2: ens_linear
A3: 1 | B3: 0.83851552 | C3: 0.86575329 | D3: 0.99381741 | E3: 0.85528463 | F3: 1.0415156 | G3: 0.70132166 | H3: 1.4101065 | I3: 0.95989138 | J3: 1.09133 | K3: 1.0318738 | L3: 0.97570197 | M3: 0.86749925 | N3: 0.95686053 | O3: 0.75292806 | P3: 0.77458994 | Q3: 0.62760565 | R3: 0.56076467 | S3: 0.55014984 | T3: 0.71737618 | U3: 0.60576569 | V3: 0.75384725 | W3: 0.19808782 | X3: 0.46663866 | Y3: 0.34755939 | Z3: 0.43636745 | AA3: 0.44647451 | AB3: 0.61748623 | AC3: 0.46633173 | AD3: 0.73700154 | AE3: 0.68789693
A4: 2 | B4: 1.1979602 | C4: 0.85256905 | D4: 0.98747079 | E4: 0.72386524 | F4: 1.0407336 | G4: 0.59283734 | H4: 0.85300901 | I4: 1.0558482 | J4: 1.0174532 | K4: 0.88763878 | L4: 0.71473373 | M4: 0.7904983 | N4: 0.66462578 | O4: 0.52713417 | P4: 0.50103354 | Q4: 0.47088285 | R4: 0.72934744 | S4: 0.77741574 | T4: 0.7949365 | U4: 0.87146218 | V4: 0.91049826 | W4: 0.74255459 | X4: 0.65511904 | Y4: 0.67252762 | Z4: 0.81119663 | AA4: 0.82168227 | AB4: 0.75762928 | AC4: 0.83249898 | AD4: 0.91036813 | AE4: 0.90410478
A5: 3 | B5: 2.1693501 | C5: 0.74232052 | D5: 1.4872993 | E5: 1.1551183 | F5: 1.4307036 | G5: 1.0378825 | H5: 1.4089119 | I5: 1.2604506 | J5: 1.3873314 | K5: 1.2940024 | L5: 0.91619378 | M5: 0.69709525 | N5: 0.68547153 | O5: 0.70170848 | P5: 0.56251309 | Q5: 0.061043884 | R5: 0.87139524 | S5: 0.301191 | T5: 0.65564835 | U5: 0.46864416 | V5: 0.6970466 | W5: 0.41560296 | X5: 0.56788269 | Y5: 0.50331607 | Z5: 0.55181813 | AA5: 0.73709367 | AB5: 0.86492181 | AC5: 0.86046435 | AD5: 0.85064491 | AE5: 0.8971622
A6: 4 | B6: 1.3988222 | C6: 0.97129762 | D6: 1.0858303 | E6: 1.1146603 | F6: 0.95336656 | G6: 1.0799406 | H6: 1.093307 | I6: 1.0655829 | J6: 1.1053782 | K6: 1.0310458 | L6: 0.94208551 | M6: 0.91066026 | N6: 0.83841153 | O6: 0.9202881 | P6: 0.93974072 | Q6: 0.16204281 | R6: 0.49108633 | S6: 0.25513813 | T6: 0.40195053 | U6: 0.50608848 | V6: 0.32994635 | W6: 0.43298007 | X6: 0.2931444 | Y6: 0.27081657 | Z6: 0.3445077 | AA6: 0.4726782 | AB6: 0.53557006 | AC6: 0.60756419 | AD6: 0.46157512 | AE6: 0.47510741
A7: 5 | B7: 0.68816692 | C7: 0.56957851 | D7: 0.97320837 | E7: 1.2505943 | F7: 0.77166513 | G7: 0.67661249 | H7: 0.81073866 | I7: 0.85602142 | J7: 0.84231238 | K7: 0.95332981 | L7: 0.64656846 | M7: 0.66091214 | N7: 0.50862883 | O7: 0.60129696 | P7: 0.57771357 | Q7: 0.81494349 | R7: 0.81423754 | S7: 0.40327559 | T7: 0.32785925 | U7: 0.73602059 | V7: 0.74009234 | W7: 0.79132884 | X7: 0.50599291 | Y7: 0.55012002 | Z7: 0.40601075 | AA7: 0.74418867 | AB7: 0.78664216 | AC7: 0.85016494 | AD7: 0.81377439 | AE7: 0.81080039
A8: 6 | B8: 1.3502125 | C8: 1.4820457 | D8: 1.0787127 | E8: 1.2073655 | F8: 0.87383433 | G8: 1.1898544 | H8: 0.963176 | I8: 0.91758124 | J8: 1.0971543 | K8: 0.83055792 | L8: 1.0078742 | M8: 1.1853864 | N8: 1.1806175 | O8: 0.9200301 | P8: 0.81046062 | Q8: 0.16852754 | R8: 0.35779839 | S8: 0.094449927 | T8: 0.31847216 | U8: 0.20630178 | V8: 0.31500888 | W8: 0.27782228 | X8: 0.1768188 | Y8: 0.022209454 | Z8: 0.26176036 | AA8: 0.44550557 | AB8: 0.32479201 | AC8: 0.33527246 | AD8: 0.393986 | AE8: 0.46341781
A9: 7 | B9: 0.94165988 | C9: 0.90028287 | D9: 1.027153 | E9: 1.0376989 | F9: 1.1042069 | G9: 1.1157666 | H9: 0.97610038 | I9: 1.1446688 | J9: 1.3127346 | K9: 1.1919214 | L9: 1.0318226 | M9: 1.1499953 | N9: 1.089 | O9: 0.98588752 | P9: 0.93822906 | Q9: 0.77223168 | R9: 0.66178329 | S9: 0.45061596 | T9: 0.45312739 | U9: 0.47375313 | V9: 0.33936435 | W9: 0.6029834 | X9: 0.27295557 | Y9: 0.021765966 | Z9: 0.13145478 | AA9: 0.49925177 | AB9: 0.20579571 | AC9: 0.37554527 | AD9: 0.63464675 | AE9: 0.6794446
A10: 8 | B10: 1.1552927 | C10: 0.89066172 | D10: 0.8795374 | E10: 0.98818643 | F10: 1.0729289 | G10: 1.0910672 | H10: 1.2781093 | I10: 0.74742816 | J10: 1.0817885 | K10: 0.99734498 | L10: 0.93979335 | M10: 1.0617793 | N10: 0.96312339 | O10: 1.0001707 | P10: 0.81864114 | Q10: 0.28019472 | R10: 0.45584667 | S10: 0.46475729 | T10: 0.33353215 | U10: 0.18089079 | V10: 0.1323423 | W10: 0.039669322 | X10: 0.66894685 | Y10: 0.15412239 | Z10: 0.27605824 | AA10: 0.46245743 | AB10: 0.18185702 | AC10: 0.33040061 | AD10: 0.49624788 | AE10: 0.71736722
A11: 9 | B11: 1.6499281 | C11: 0.91984425 | D11: 1.0841392 | E11: 0.69491674 | F11: 1.3081862 | G11: 0.88465183 | H11: 0.97019 | I11: 1.0811073 | J11: 1.179035 | K11: 1.0416467 | L11: 0.88965363 | M11: 0.85300906 | N11: 0.89843605 | O11: 0.79134065 | P11: 0.87435601 | Q11: 0.24927608 | R11: 0.76807872 | S11: 0.78535755 | T11: 0.88132546 | U11: 0.86836417 | V11: 0.88659408 | W11: 0.73813483 | X11: 0.75315712 | Y11: 0.79931499 | Z11: 0.84115049 | AA11: 0.83155916 | AB11: 0.87991923 | AC11: 0.84621007 | AD11: 0.89010546 | AE11: 0.82723076
A12: 10 | B12: 1.075561 | C12: 1.1285605 | D12: 0.97001096 | E12: 1.1534597 | F12: 1.3026136 | G12: 1.2247155 | H12: 0.91054979 | I12: 1.2140544 | J12: 1.1385166 | K12: 1.1556889 | L12: 1.1750766 | M12: 1.2668467 | N12: 1.2542594 | O12: 1.0418161 | P12: 0.96803853 | Q12: 0.70756323 | R12: 0.60652285 | S12: 0.73771151 | T12: 0.57836796 | U12: 0.53252237 | V12: 0.47728459 | W12: 0.72241708 | X12: 0.57058277 | Y12: 0.57527977 | Z12: 0.61808768 | AA12: 0.54792565 | AB12: 0.41027067 | AC12: 0.42280773 | AD12: 0.67609301 | AE12: 0.73872167
A14: AVG | B14: =AVERAGE(B3:B12) -> 1.2465469 | C14: =AVERAGE(C3:C12) -> 0.9322914 | D14: =AVERAGE(D3:D12) -> 1.0567179 | E14: =AVERAGE(E3:E12) -> 1.018115 | F14: =AVERAGE(F3:F12) -> 1.0899754 | G14: =AVERAGE(G3:G12) -> 0.95946501 | H14: =AVERAGE(H3:H12) -> 1.0674199 | I14: =AVERAGE(I3:I12) -> 1.0302634 | ... AE14: =AVERAGE(AE3:AE12) -> 0.72012538
A15: MEDIAN | B15: =MEDIAN(B3:B12) -> 1.1766264 | C15: =MEDIAN(C3:C12) -> 0.8954723 | D15: =MEDIAN(D3:D12) -> 1.0104852 | E15: =MEDIAN(E3:E12) -> 1.0761796 | F15: =MEDIAN(F3:F12) -> 1.0572223 | G15: =MEDIAN(G3:G12) -> 1.0589115 | H15: =MEDIAN(H3:H12) -> 0.97314519 | I15: =MEDIAN(I3:I12) -> 1.0607155 | ... AE15: =MEDIAN(AE3:AE12) -> 0.72804445

Sheet Combined
C1: RMSE | R1: R2
C2: rvmRadial | D2: rvmPoly | E2: svmRadial | F2: svmPoly | G2: gaussprRadial | H2: gaussprPoly | I2: nnet | J2: knn | K2: treebag | L2: rf | M2: cubist | N2: pls | O2: pcr | P2: ens_greedy | Q2: ens_linear | R2: rvmRadial | S2: rvmPoly | T2: svmRadial | U2: svmPoly | V2: gaussprRadial | W2: gaussprPoly | X2: nnet | Y2: knn | Z2: treebag | AA2: rf | AB2: cubist | AC2: pls | AD2: pcr | AE2: ens_greedy | AF2: ens_linear
A3: 102 | B3: 1 | C3: ='102'!B3 -> 0.67183088 | D3: ='102'!C3 -> 0.67802811 | E3: ='102'!D3 -> 0.86692734 | F3: ='102'!E3 -> 0.82015766 | G3: ='102'!F3 -> 1.022861 | H3: ='102'!G3 -> 0.87570573 | I3: ='102'!H3 -> 0.77424315 | J3: ='102'!I3 -> 0.76704237 | ... AF3: ='102'!AE3 -> 0.85023372
B4: 2 | C4: ='102'!B4 -> 1.2640447 | D4: ='102'!C4 -> 1.198097 | E4: ='102'!D4 -> 0.95393463 | F4: ='102'!E4 -> 1.1607483 | G4: ='102'!F4 -> 1.1975137 | H4: ='102'!G4 -> 1.2585423 | I4: ='102'!H4 -> 1.2553674 | J4: ='102'!I4 -> 1.0377838 | ... AF4: ='102'!AE4 -> 0.55645329
B5: 3 | C5: ='102'!B5 -> 1.0151856 | D5: ='102'!C5 -> 0.85889019 | E5: ='102'!D5 -> 0.97108402 | F5: ='102'!E5 -> 0.64947672 | G5: ='102'!F5 -> 1.0188892 | H5: ='102'!G5 -> 0.79929365 | I5: ='102'!H5 -> 0.91828198 | J5: ='102'!I5 -> 1.0872868 | ... AF5: ='102'!AE5 -> 0.68784561
B6: 4 | C6: ='102'!B6 -> 0.59543381 | D6: ='102'!C6 -> 0.597103 | E6: ='102'!D6 -> 0.80610019 | F6: ='102'!E6 -> 0.73269901 | G6: ='102'!F6 -> 0.86352175 | H6: ='102'!G6 -> 0.78027654 | I6: ='102'!H6 -> 1.2536188 | J6: ='102'!I6 -> 0.72626544 | ... AF6: ='102'!AE6 -> 0.80927278
B7: 5 | C7: ='102'!B7 -> 0.90838191 | D7: ='102'!C7 -> 0.83796286 | E7: ='102'!D7 -> 0.77630413 | F7: ='102'!E7 -> 0.81127304 | G7: ='102'!F7 -> 0.95470595 | H7: ='102'!G7 -> 0.8441889 | I7: ='102'!H7 -> 1.0461025 | J7: ='102'!I7 -> 0.93347782 | ... AF7: ='102'!AE7 -> 0.45506582
B8: 6 | C8: ='102'!B8 -> 1.2776999 | D8: ='102'!C8 -> 1.3078632 | E8: ='102'!D8 -> 0.77447929 | F8: ='102'!E8 -> 1.2617449 | G8: ='102'!F8 -> 0.80057655 | H8: ='102'!G8 -> 1.1616237 | I8: ='102'!H8 -> 1.4880093 | J8: ='102'!I8 -> 1.1513447 | ... AF8: ='102'!AE8 -> 0.12048193
B9: 7 | C9: ='102'!B9 -> 0.70925408 | D9: ='102'!C9 -> 0.59434097 | E9: ='102'!D9 -> 0.75011505 | F9: ='102'!E9 -> 0.61058186 | G9: ='102'!F9 -> 0.76673414 | H9: ='102'!G9 -> 0.80046278 | I9: ='102'!H9 -> 0.88250988 | J9: ='102'!I9 -> 0.91892238 | ... AF9: ='102'!AE9 -> 0.55481081
B10: 8 | C10: ='102'!B10 -> 0.80636229 | D10: ='102'!C10 -> 0.74326007 | E10: ='102'!D10 -> 0.52276947 | F10: ='102'!E10 -> 0.61968934 | G10: ='102'!F10 -> 0.72618012 | H10: ='102'!G10 -> 0.54517832 | I10: ='102'!H10 -> 0.69979969 | J10: ='102'!I10 -> 0.6128222 | ... AF10: ='102'!AE10 -> 0.74147827
B11: 9 | C11: ='102'!B11 -> 1.0181375 | D11: ='102'!C11 -> 0.88366639 | E11: ='102'!D11 -> 0.3912393 | F11: ='102'!E11 -> 0.74537142 | G11: ='102'!F11 -> 0.40392584 | H11: ='102'!G11 -> 0.6480564 | I11: ='102'!H11 -> 0.74901531 | J11: ='102'!I11 -> 0.60907799 | ... AF11: ='102'!AE11 -> 0.78992928
B12: 10 | C12: ='102'!B12 -> 0.82025141 | D12: ='102'!C12 -> 0.6101141 | E12: ='102'!D12 -> 0.70683515 | F12: ='102'!E12 -> 0.60874679 | G12: ='102'!F12 -> 0.75296184 | H12: ='102'!G12 -> 0.62809488 | I12: ='102'!H12 -> 0.90697537 | J12: ='102'!I12 -> 0.8604871 | ... AF12: ='102'!AE12 -> 0.87541409
A13: 459 | B13: 1 | C13: ='459'!B3 -> 1.0110117 | D13: ='459'!C3 -> 1.1050954 | E13: ='459'!D3 -> 1.2437336 | F13: ='459'!E3 -> 1.2678096 | G13: ='459'!F3 -> 1.1920326 | H13: ='459'!G3 -> 1.2107111 | I13: ='459'!H3 -> 1.2476421 | J13: ='459'!I3 -> 1.2590637 | ... AF13: ='459'!AE3 -> 0.29660644
B14: 2 | C14: ='459'!B4 -> 0.77172028 | D14: ='459'!C4 -> 0.72566267 | E14: ='459'!D4 -> 0.87634704 | F14: ='459'!E4 -> 0.66675357 | G14: ='459'!F4 -> 0.87212405 | H14: ='459'!G4 -> 1.1883816 | I14: ='459'!H4 -> 0.84162761 | J14: ='459'!I4 -> 0.79557545 | ... AF14: ='459'!AE4 -> 0.54741228
B15: 3 | C15: ='459'!B5 -> 1.2204064 | D15: ='459'!C5 -> 0.98630267 | E15: ='459'!D5 -> 1.1390039 | F15: ='459'!E5 -> 0.89430091 | G15: ='459'!F5 -> 1.2546549 | H15: ='459'!G5 -> 0.91536555 | I15: ='459'!H5 -> 0.90117543 | J15: ='459'!I5 -> 1.1797819 | ... AF15: ='459'!AE5 -> 0.68249957
B16: 4 | C16: ='459'!B6 -> 2.344952 | D16: ='459'!C6 -> 0.96035173 | E16: ='459'!D6 -> 1.7829693 | F16: ='459'!E6 -> 1.2407117 | G16: ='459'!F6 -> 1.7468594 | H16: ='459'!G6 -> 1.3054421 | I16: ='459'!H6 -> 1.8316501 | J16: ='459'!I6 -> 1.4069594 | ... AF16: ='459'!AE6 -> 0.83558787
B17: 5 | C17: ='459'!B7 -> 1.1023715 | D17: ='459'!C7 -> 0.94564468 | E17: ='459'!D7 -> 1.0585712 | F17: ='459'!E7 -> 1.2614865 | G17: ='459'!F7 -> 0.77119105 | H17: ='459'!G7 -> 1.1247197 | I17: ='459'!H7 -> 1.8198128 | J17: ='459'!I7 -> 1.0581743 | ... AF17: ='459'!AE7 -> 0.15583825
B18: 6 | C18: ='459'!B8 -> 1.1448525 | D18: ='459'!C8 -> 0.82378768 | E18: ='459'!D8 -> 0.7125806 | F18: ='459'!E8 -> 0.79307535 | G18: ='459'!F8 -> 1.0927902 | H18: ='459'!G8 -> 0.78829964 | I18: ='459'!H8 -> 0.88020947 | J18: ='459'!I8 -> 0.99092051 | ... AF18: ='459'!AE8 -> 0.90788572
B19: 7 | C19: ='459'!B9 -> 1.3017051 | D19: ='459'!C9 -> 0.98496096 | E19: ='459'!D9 -> 1.1267403 | F19: ='459'!E9 -> 0.91986127 | G19: ='459'!F9 -> 1.156445 | H19: ='459'!G9 -> 0.92857318 | I19: ='459'!H9 -> 1.311318 | J19: ='459'!I9 -> 1.0805383 | ... AF19: ='459'!AE9 -> 0.85772589
B20: 8 | C20: ='459'!B10 -> 0.9751789 | D20: ='459'!C10 -> 0.53281367 | E20: ='459'!D10 -> 0.7762799 | F20: ='459'!E10 -> 0.5014589 | G20: ='459'!F10 -> 0.76224812 | H20: ='459'!G10 -> 0.70074937 | I20: ='459'!H10 -> 1.2890184 | J20: ='459'!I10 -> 0.87033229 | ... AF20: ='459'!AE10 -> 0.50314939
B21: 9 | C21: ='459'!B11 -> 0.7952844 | D21: ='459'!C11 -> 0.85343352 | E21: ='459'!D11 -> 0.82401979 | F21: ='459'!E11 -> 0.82032953 | G21: ='459'!F11 -> 0.84017786 | H21: ='459'!G11 -> 0.74924914 | I21: ='459'!H11 -> 1.1569916 | J21: ='459'!I11 -> 0.84986783 | ... AF21: ='459'!AE11 -> 0.65501006
B22: 10 | C22: ='459'!B12 -> 0.87680974 | D22: ='459'!C12 -> 0.72579854 | E22: ='459'!D12 -> 0.68785324 | F22: ='459'!E12 -> 0.81499758 | G22: ='459'!F12 -> 0.85031937 | H22: ='459'!G12 -> 0.72473915 | I22: ='459'!H12 -> 0.80454324 | J22: ='459'!I12 -> 0.74016891 | ... AF22: ='459'!AE12 -> 0.7246286
A23: 854 | B23: 1 | C23: ='854'!B3 -> 0.57481939 | D23: ='854'!C3 -> 0.91213115 | E23: ='854'!D3 -> 0.80821936 | F23: ='854'!E3 -> 0.89730892 | G23: ='854'!F3 -> 0.81000779 | H23: ='854'!G3 -> 0.81516248 | I23: ='854'!H3 -> 1.1358113 | J23: ='854'!I3 -> 0.75346953 | ... AF23: ='854'!AE3 -> 0.54517918
B24: 2 | C24: ='854'!B4 -> 0.9101253 | D24: ='854'!C4 -> 0.79617098 | E24: ='854'!D4 -> 0.6543988 | F24: ='854'!E4 -> 0.9232723 | G24: ='854'!F4 -> 0.91412856 | H24: ='854'!G4 -> 0.91502459 | I24: ='854'!H4 -> 0.99134396 | J24: ='854'!I4 -> 0.7874554 | ... AF24: ='854'!AE4 -> 0.57392885
B25: 3 | C25: ='854'!B5 -> 1.0192864 | D25: ='854'!C5 -> 1.2103357 | E25: ='854'!D5 -> 1.1419288 | F25: ='854'!E5 -> 1.3693213 | G25: ='854'!F5 -> 1.445469 | H25: ='854'!G5 -> 1.3790299 | I25: ='854'!H5 -> 1.1897473 | J25: ='854'!I5 -> 1.2684192 | ... AF25: ='854'!AE5 -> 0.65288408
B26: 4 | C26: ='854'!B6 -> 1.0386991 | D26: ='854'!C6 -> 1.0189778 | E26: ='854'!D6 -> 1.1148954 | F26: ='854'!E6 -> 1.0036755 | G26: ='854'!F6 -> 1.0484944 | H26: ='854'!G6 -> 1.0407544 | I26: ='854'!H6 -> 1.2374965 | J26: ='854'!I6 -> 1.033 | ... AF26: ='854'!AE6 -> 0.34466925
B27: 5 | C27: ='854'!B7 -> 1.0050585 | D27: ='854'!C7 -> 1.1177209 | E27: ='854'!D7 -> 0.94443634 | F27: ='854'!E7 -> 1.0558735 | G27: ='854'!F7 -> 1.2223926 | H27: ='854'!G7 -> 1.115044 | I27: ='854'!H7 -> 0.78088522 | J27: ='854'!I7 -> 1.0477829 | ... AF27: ='854'!AE7 -> 0.68841126
B28: 6 | C28: ='854'!B8 -> 1.6264752 | D28: ='854'!C8 -> 1.1312881 | E28: ='854'!D8 -> 0.9826516 | F28: ='854'!E8 -> 1.009674 | G28: ='854'!F8 -> 1.2304478 | H28: ='854'!G8 -> 1.1060051 | I28: ='854'!H8 -> 0.83908683 | J28: ='854'!I8 -> 1.2670973 | ... AF28: ='854'!AE8 -> 0.56021085
B29: 7 | C29: ='854'!B9 -> 0.98960281 | D29: ='854'!C9 -> 0.850562 | E29: ='854'!D9 -> 0.95940048 | F29: ='854'!E9 -> 0.85743541 | G29: ='854'!F9 -> 0.93547025 | H29: ='854'!G9 -> 0.92540845 | I29: ='854'!H9 -> 0.86074528 | J29: ='854'!I9 -> 0.66849466 | ... AF29: ='854'!AE9 -> 0.52588736
B30: 8 | C30: ='854'!B10 -> 1.0819018 | D30: ='854'!C10 -> 1.0172906 | E30: ='854'!D10 -> 0.84724545 | F30: ='854'!E10 -> 0.87147007 | G30: ='854'!F10 -> 1.0219832 | H30: ='854'!G10 -> 0.92383515 | I30: ='854'!H10 -> 1.2928234 | J30: ='854'!I10 -> 0.95056323 | ... AF30: ='854'!AE10 -> 0.63711478
B31: 9 | C31: ='854'!B11 -> 1.594231 | D31: ='854'!C11 -> 1.1706908 | E31: ='854'!D11 -> 0.89656104 | F31: ='854'!E11 -> 0.98895421 | G31: ='854'!F11 -> 1.0245563 | H31: ='854'!G11 -> 0.87988678 | I31: ='854'!H11 -> 1.3687663 | J31: ='854'!I11 -> 0.96989392 | ... AF31: ='854'!AE11 -> 0.2678302
B32: 10 | C32: ='854'!B12 -> 0.89141111 | D32: ='854'!C12 -> 0.85620952 | E32: ='854'!D12 -> 0.93107911 | F32: ='854'!E12 -> 1.6534045 | G32: ='854'!F12 -> 0.86850802 | H32: ='854'!G12 -> 1.0975562 | I32: ='854'!H12 -> 1.2497656 | J32: ='854'!I12 -> 0.67703988 | ... AF32: ='854'!AE12 -> 0.67461918
A33: 912 | B33: 1 | C33: ='912'!B3 -> 0.92342382 | D33: ='912'!C3 -> 0.70848736 | E33: ='912'!D3 -> 0.70219521 | F33: ='912'!E3 -> 0.83636987 | G33: ='912'!F3 -> 0.99654666 | H33: ='912'!G3 -> 0.72105082 | I33: ='912'!H3 -> 0.9279322 | J33: ='912'!I3 -> 0.96314987 | ... AF33: ='912'!AE3 -> 0.86604
B34: 2 | C34: ='912'!B4 -> 1.2412726 | D34: ='912'!C4 -> 0.98740124 | E34: ='912'!D4 -> 0.97283037 | F34: ='912'!E4 -> 0.99782929 | G34: ='912'!F4 -> 1.0351968 | H34: ='912'!G4 -> 0.98012486 | I34: ='912'!H4 -> 1.227837 | J34: ='912'!I4 -> 0.93826222 | ... AF34: ='912'!AE4 -> 0.21158997
B35: 3 | C35: ='912'!B5 -> 1.1997805 | D35: ='912'!C5 -> 1.1918441 | E35: ='912'!D5 -> 1.1879638 | F35: ='912'!E5 -> 1.110613 | G35: ='912'!F5 -> 1.1578356 | H35: ='912'!G5 -> 1.0516609 | I35: ='912'!H5 -> 1.4764634 | J35: ='912'!I5 -> 1.2777859 | ... AF35: ='912'!AE5 -> 0.31409448
B36: 4 | C36: ='912'!B6 -> 0.89450821 | D36: ='912'!C6 -> 0.91828208 | E36: ='912'!D6 -> 0.77885074 | F36: ='912'!E6 -> 0.85732283 | G36: ='912'!F6 -> 0.8675441 | H36: ='912'!G6 -> 0.83934488 | I36: ='912'!H6 -> 1.0156996 | J36: ='912'!I6 -> 0.82438785 | ... AF36: ='912'!AE6 -> 0.43527571
B37: 5 | C37: ='912'!B7 -> 0.74639797 | D37: ='912'!C7 -> 0.73504496 | E37: ='912'!D7 -> 0.73312485 | F37: ='912'!E7 -> 0.87271678 | G37: ='912'!F7 -> 0.94408188 | H37: ='912'!G7 -> 0.81985435 | I37: ='912'!H7 -> 1.2215853 | J37: ='912'!I7 -> 0.72450673 | ... AF37: ='912'!AE7 -> 0.48264998
B38: 6 | C38: ='912'!B8 -> 1.3782157 | D38: ='912'!C8 -> 0.75483861 | E38: ='912'!D8 -> 1.0550775 | F38: ='912'!E8 -> 0.746303 | G38: ='912'!F8 -> 1.2630206 | H38: ='912'!G8 -> 0.83804041 | I38: ='912'!H8 -> 0.82351052 | J38: ='912'!I8 -> 1.4042057 | ... AF38: ='912'!AE8 -> 0.84020412
B39: 7 | C39: ='912'!B9 -> 0.93210701 | D39: ='912'!C9 -> 0.97340406 | E39: ='912'!D9 -> 1.0204756 | F39: ='912'!E9 -> 1.0290558 | G39: ='912'!F9 -> 1.1102131 | H39: ='912'!G9 -> 1.0166403 | I39: ='912'!H9 -> 1.0528525 | J39: ='912'!I9 -> 0.98018458 | ... AF39: ='912'!AE9 -> 0.65391014
B40: 8 | C40: ='912'!B10 -> 1.2844553 | D40: ='912'!C10 -> 0.93918275 | E40: ='912'!D10 -> 1.0827652 | F40: ='912'!E10 -> 0.93239121 | G40: ='912'!F10 -> 1.1148622 | H40: ='912'!G10 -> 0.96248713 | I40: ='912'!H10 -> 1.19054 | J40: ='912'!I10 -> 0.87273275 | ... AF40: ='912'!AE10 -> 0.54478842
...
